
                          ____/ (  (    )   )  \___
                         /( (  (  )   _    ))  )   )\
                       ((     (   )(    )  )   (   )  )
                     ((/  ( _(   )   (   _) ) (  () )  )
                    ( (  ( (_)   ((    (   )  .((_ ) .  )_
                   ( (  )    (      (  )    )   ) . ) (   )
                  (  (   (  (   ) (  _  ( _) ).  ) . ) ) ( )
                  ( (  (   ) (  )   (  ))     ) _)(   )  )  )
                 ( (  ( \ ) (    (_  ( ) ( )  )   ) )  )) ( )
                  (  (   (  (   (_ ( ) ( _    )  ) (  )  )   )
                 ( (  ( (  (  )     (_  )  ) )  _)   ) _( ( )
                  ((  (   )(    (     _    )   _) _(_ (  (_ )
                   (_((__(_(__(( ( ( |  ) ) ) )_))__))_)___)
                   ((__)        \\||lll|l||///          \_))
                            (   /(/ (  )  ) )\   )
                          (    ( ( ( | | ) ) )\   )
                           (   /(| / ( )) ) ) )) )
                         (     ( ((((_(|)_)))))     )
                          (      ||\(|(|)|/||     )
                        (        |(||(||)||||        )
                          (     //|/l|||)|\\ \     )
                        (/ / //  /|//||||\\  \ \  \ _)
-------------------------------------------------------------------------------
Node: MSI.localdomain
-------------------------------------------------------------------------------
Traceback (most recent call last):
  File "/home/aditya/.local/lib/python3.7/site-packages/sqlalchemy/engine/base.py", line 1277, in _execute_context
    cursor, statement, parameters, context
  File "/home/aditya/.local/lib/python3.7/site-packages/sqlalchemy/engine/default.py", line 593, in do_execute
    cursor.execute(statement, parameters)
psycopg2.errors.UndefinedColumn: column dag.root_dag_id does not exist
LINE 1: SELECT dag.dag_id AS dag_dag_id, dag.root_dag_id AS dag_root...
                                         ^


The above exception was the direct cause of the following exception:

Traceback (most recent call last):
  File "/home/aditya/.local/lib/python3.7/site-packages/flask/app.py", line 2447, in wsgi_app
    response = self.full_dispatch_request()
  File "/home/aditya/.local/lib/python3.7/site-packages/flask/app.py", line 1952, in full_dispatch_request
    rv = self.handle_user_exception(e)
  File "/home/aditya/.local/lib/python3.7/site-packages/flask/app.py", line 1821, in handle_user_exception
    reraise(exc_type, exc_value, tb)
  File "/home/aditya/.local/lib/python3.7/site-packages/flask/_compat.py", line 39, in reraise
    raise value
  File "/home/aditya/.local/lib/python3.7/site-packages/flask/app.py", line 1950, in full_dispatch_request
    rv = self.dispatch_request()
  File "/home/aditya/.local/lib/python3.7/site-packages/flask/app.py", line 1936, in dispatch_request
    return self.view_functions[rule.endpoint](**req.view_args)
  File "/home/aditya/.local/lib/python3.7/site-packages/flask_admin/base.py", line 69, in inner
    return self._run_view(f, *args, **kwargs)
  File "/home/aditya/.local/lib/python3.7/site-packages/flask_admin/base.py", line 368, in _run_view
    return fn(self, *args, **kwargs)
  File "/home/aditya/.local/lib/python3.7/site-packages/flask_login/utils.py", line 258, in decorated_view
    return func(*args, **kwargs)
  File "/home/aditya/.local/lib/python3.7/site-packages/airflow/utils/db.py", line 74, in wrapper
    return func(*args, **kwargs)
  File "/home/aditya/.local/lib/python3.7/site-packages/airflow/www/views.py", line 2306, in index
    dags = query.offset(start).limit(dags_per_page).all()
  File "/home/aditya/.local/lib/python3.7/site-packages/sqlalchemy/orm/query.py", line 3346, in all
    return list(self)
  File "/home/aditya/.local/lib/python3.7/site-packages/sqlalchemy/orm/query.py", line 3508, in __iter__
    return self._execute_and_instances(context)
  File "/home/aditya/.local/lib/python3.7/site-packages/sqlalchemy/orm/query.py", line 3533, in _execute_and_instances
    result = conn.execute(querycontext.statement, self._params)
  File "/home/aditya/.local/lib/python3.7/site-packages/sqlalchemy/engine/base.py", line 1011, in execute
    return meth(self, multiparams, params)
  File "/home/aditya/.local/lib/python3.7/site-packages/sqlalchemy/sql/elements.py", line 298, in _execute_on_connection
    return connection._execute_clauseelement(self, multiparams, params)
  File "/home/aditya/.local/lib/python3.7/site-packages/sqlalchemy/engine/base.py", line 1130, in _execute_clauseelement
    distilled_params,
  File "/home/aditya/.local/lib/python3.7/site-packages/sqlalchemy/engine/base.py", line 1317, in _execute_context
    e, statement, parameters, cursor, context
  File "/home/aditya/.local/lib/python3.7/site-packages/sqlalchemy/engine/base.py", line 1511, in _handle_dbapi_exception
    sqlalchemy_exception, with_traceback=exc_info[2], from_=e
  File "/home/aditya/.local/lib/python3.7/site-packages/sqlalchemy/util/compat.py", line 182, in raise_
    raise exception
  File "/home/aditya/.local/lib/python3.7/site-packages/sqlalchemy/engine/base.py", line 1277, in _execute_context
    cursor, statement, parameters, context
  File "/home/aditya/.local/lib/python3.7/site-packages/sqlalchemy/engine/default.py", line 593, in do_execute
    cursor.execute(statement, parameters)
sqlalchemy.exc.ProgrammingError: (psycopg2.errors.UndefinedColumn) column dag.root_dag_id does not exist
LINE 1: SELECT dag.dag_id AS dag_dag_id, dag.root_dag_id AS dag_root...
                                         ^

[SQL: SELECT dag.dag_id AS dag_dag_id, dag.root_dag_id AS dag_root_dag_id, dag.is_paused AS dag_is_paused, dag.is_subdag AS dag_is_subdag, dag.is_active AS dag_is_active, dag.last_scheduler_run AS dag_last_scheduler_run, dag.last_pickled AS dag_last_pickled, dag.last_expired AS dag_last_expired, dag.scheduler_lock AS dag_scheduler_lock, dag.pickle_id AS dag_pickle_id, dag.fileloc AS dag_fileloc, dag.owners AS dag_owners, dag.description AS dag_description, dag.default_view AS dag_default_view, dag.schedule_interval AS dag_schedule_interval 
FROM dag 
WHERE NOT dag.is_subdag AND dag.is_active ORDER BY dag.dag_id 
 LIMIT %(param_1)s OFFSET %(param_2)s]
[parameters: {'param_1': 100, 'param_2': 0}]
(Background on this error at: http://sqlalche.me/e/13/f405)