[2020-09-03 00:18:55,488] {taskinstance.py:670} INFO - Dependencies all met for <TaskInstance: alt_ingestion_pipeline.refresh_auction_listing 2020-09-02T00:00:00+00:00 [queued]>
[2020-09-03 00:18:55,520] {taskinstance.py:670} INFO - Dependencies all met for <TaskInstance: alt_ingestion_pipeline.refresh_auction_listing 2020-09-02T00:00:00+00:00 [queued]>
[2020-09-03 00:18:55,521] {taskinstance.py:880} INFO - 
--------------------------------------------------------------------------------
[2020-09-03 00:18:55,521] {taskinstance.py:881} INFO - Starting attempt 2 of 2
[2020-09-03 00:18:55,521] {taskinstance.py:882} INFO - 
--------------------------------------------------------------------------------
[2020-09-03 00:18:55,550] {taskinstance.py:901} INFO - Executing <Task(PythonOperator): refresh_auction_listing> on 2020-09-02T00:00:00+00:00
[2020-09-03 00:18:55,571] {standard_task_runner.py:54} INFO - Started process 815 to run task
[2020-09-03 00:18:55,618] {standard_task_runner.py:77} INFO - Running: ['airflow', 'run', 'alt_ingestion_pipeline', 'refresh_auction_listing', '2020-09-02T00:00:00+00:00', '--job_id', '16', '--pool', 'default_pool', '--raw', '-sd', 'DAGS_FOLDER/alt_ingestion_pipeline.py', '--cfg_path', '/tmp/tmpvgvb4_52']
[2020-09-03 00:18:55,620] {standard_task_runner.py:78} INFO - Job 16: Subtask refresh_auction_listing
[2020-09-03 00:18:55,822] {logging_mixin.py:112} INFO - Running %s on host %s <TaskInstance: alt_ingestion_pipeline.refresh_auction_listing 2020-09-02T00:00:00+00:00 [running]> MSI.localdomain
[2020-09-03 00:19:02,256] {taskinstance.py:1150} ERROR - name 'indAll' is not defined
Traceback (most recent call last):
  File "/home/aditya/.local/lib/python3.7/site-packages/airflow/models/taskinstance.py", line 984, in _run_raw_task
    result = task_copy.execute(context=context)
  File "/home/aditya/.local/lib/python3.7/site-packages/airflow/operators/python_operator.py", line 113, in execute
    return_value = self.execute_callable()
  File "/home/aditya/.local/lib/python3.7/site-packages/airflow/operators/python_operator.py", line 118, in execute_callable
    return self.python_callable(*self.op_args, **self.op_kwargs)
  File "/mnt/c/Users/adity/Downloads/Interview/Alt_DE/psacard/loadall_auction_items.py", line 41, in main
    fetch_auction_items(AUCTION_PRICES_PATH, BASE_PATH, SAVE_PATH, 'w')
  File "/mnt/c/Users/adity/Downloads/Interview/Alt_DE/psacard/loadall_auction_items.py", line 29, in fetch_auction_items
    item_info['count'] = int(item.f-indAll('td')[-1].contents[0])
NameError: name 'indAll' is not defined
[2020-09-03 00:19:02,261] {taskinstance.py:1194} INFO - Marking task as FAILED. dag_id=alt_ingestion_pipeline, task_id=refresh_auction_listing, execution_date=20200902T000000, start_date=20200903T041855, end_date=20200903T041902
[2020-09-03 00:19:02,305] {configuration.py:373} WARNING - section/key [smtp/smtp_user] not found in config
[2020-09-03 00:19:02,306] {configuration.py:373} WARNING - section/key [smtp/smtp_user] not found in config
[2020-09-03 00:19:02,307] {taskinstance.py:1200} ERROR - Failed to send email to: ['akroy@umass.edu']
[2020-09-03 00:19:02,307] {taskinstance.py:1201} ERROR - [Errno 111] Connection refused
Traceback (most recent call last):
  File "/home/aditya/.local/lib/python3.7/site-packages/airflow/models/taskinstance.py", line 984, in _run_raw_task
    result = task_copy.execute(context=context)
  File "/home/aditya/.local/lib/python3.7/site-packages/airflow/operators/python_operator.py", line 113, in execute
    return_value = self.execute_callable()
  File "/home/aditya/.local/lib/python3.7/site-packages/airflow/operators/python_operator.py", line 118, in execute_callable
    return self.python_callable(*self.op_args, **self.op_kwargs)
  File "/mnt/c/Users/adity/Downloads/Interview/Alt_DE/psacard/loadall_auction_items.py", line 41, in main
    fetch_auction_items(AUCTION_PRICES_PATH, BASE_PATH, SAVE_PATH, 'w')
  File "/mnt/c/Users/adity/Downloads/Interview/Alt_DE/psacard/loadall_auction_items.py", line 29, in fetch_auction_items
    item_info['count'] = int(item.f-indAll('td')[-1].contents[0])
NameError: name 'indAll' is not defined

During handling of the above exception, another exception occurred:

Traceback (most recent call last):
  File "/home/aditya/.local/lib/python3.7/site-packages/airflow/models/taskinstance.py", line 1473, in email_alert
    send_email(self.task.email, subject, html_content)
  File "/home/aditya/.local/lib/python3.7/site-packages/airflow/utils/email.py", line 62, in send_email
    mime_subtype=mime_subtype, mime_charset=mime_charset, **kwargs)
  File "/home/aditya/.local/lib/python3.7/site-packages/airflow/utils/email.py", line 108, in send_email_smtp
    send_MIME_email(smtp_mail_from, recipients, msg, dryrun)
  File "/home/aditya/.local/lib/python3.7/site-packages/airflow/utils/email.py", line 127, in send_MIME_email
    s = smtplib.SMTP_SSL(SMTP_HOST, SMTP_PORT) if SMTP_SSL else smtplib.SMTP(SMTP_HOST, SMTP_PORT)
  File "/home/aditya/anaconda3/lib/python3.7/smtplib.py", line 251, in __init__
    (code, msg) = self.connect(host, port)
  File "/home/aditya/anaconda3/lib/python3.7/smtplib.py", line 336, in connect
    self.sock = self._get_socket(host, port, self.timeout)
  File "/home/aditya/anaconda3/lib/python3.7/smtplib.py", line 307, in _get_socket
    self.source_address)
  File "/home/aditya/anaconda3/lib/python3.7/socket.py", line 728, in create_connection
    raise err
  File "/home/aditya/anaconda3/lib/python3.7/socket.py", line 716, in create_connection
    sock.connect(sa)
ConnectionRefusedError: [Errno 111] Connection refused

During handling of the above exception, another exception occurred:

Traceback (most recent call last):
  File "/home/aditya/.local/lib/python3.7/site-packages/airflow/models/taskinstance.py", line 1198, in handle_failure
    self.email_alert(error)
  File "/home/aditya/.local/lib/python3.7/site-packages/airflow/models/taskinstance.py", line 1475, in email_alert
    send_email(self.task.email, subject, html_content_err)
  File "/home/aditya/.local/lib/python3.7/site-packages/airflow/utils/email.py", line 62, in send_email
    mime_subtype=mime_subtype, mime_charset=mime_charset, **kwargs)
  File "/home/aditya/.local/lib/python3.7/site-packages/airflow/utils/email.py", line 108, in send_email_smtp
    send_MIME_email(smtp_mail_from, recipients, msg, dryrun)
  File "/home/aditya/.local/lib/python3.7/site-packages/airflow/utils/email.py", line 127, in send_MIME_email
    s = smtplib.SMTP_SSL(SMTP_HOST, SMTP_PORT) if SMTP_SSL else smtplib.SMTP(SMTP_HOST, SMTP_PORT)
  File "/home/aditya/anaconda3/lib/python3.7/smtplib.py", line 251, in __init__
    (code, msg) = self.connect(host, port)
  File "/home/aditya/anaconda3/lib/python3.7/smtplib.py", line 336, in connect
    self.sock = self._get_socket(host, port, self.timeout)
  File "/home/aditya/anaconda3/lib/python3.7/smtplib.py", line 307, in _get_socket
    self.source_address)
  File "/home/aditya/anaconda3/lib/python3.7/socket.py", line 728, in create_connection
    raise err
  File "/home/aditya/anaconda3/lib/python3.7/socket.py", line 716, in create_connection
    sock.connect(sa)
ConnectionRefusedError: [Errno 111] Connection refused
[2020-09-03 00:19:05,491] {local_task_job.py:102} INFO - Task exited with return code 1
